"""
Test memory failure modes and error handling scenarios.

This module tests various failure scenarios in the memory system including
vector store failures, embedding generation errors, search timeouts, and
tenant isolation during failures.
"""

from typing import Any
from unittest.mock import Mock

import pytest

from ultimate_discord_intelligence_bot.step_result import StepResult


class TestMemoryFailureModes:
    """Test memory failure modes and error handling scenarios."""

    @pytest.fixture
    def mock_vector_store(self) -> Mock:
        """Mock vector store for testing."""
        from unittest.mock import AsyncMock

        return AsyncMock()

    @pytest.fixture
    def mock_embedding_service(self) -> Mock:
        """Mock embedding service for testing."""
        return Mock()

    @pytest.fixture
    def sample_content(self) -> dict[str, Any]:
        """Sample content for testing."""
        return {
            "text": "Sample content for testing",
            "metadata": {"source": "test", "timestamp": "2025-01-04T10:00:00Z"},
            "tenant": "test_tenant",
            "workspace": "test_workspace",
        }

    @pytest.fixture
    def sample_embedding(self) -> list[float]:
        """Sample embedding for testing."""
        return [0.1, 0.2, 0.3, 0.4, 0.5, 0.1, 0.2, 0.3, 0.4, 0.5]

    # Vector Store Connection Tests

    @pytest.mark.asyncio
    async def test_vector_store_connection_failure(self, mock_vector_store: Mock) -> None:
        """Test vector store connection failure handling."""
        # Mock connection failure
        mock_vector_store.connect.return_value = StepResult(
            success=False,
            error="Connection failed: Network unreachable",
            retryable=True,
            custom_status="retryable",
        )

        result = await mock_vector_store.connect()

        assert not result.success
        assert result["status"] == "retryable"
        assert "Connection failed" in result.error

    @pytest.mark.asyncio
    async def test_vector_store_connection_timeout(self, mock_vector_store: Mock) -> None:
        """Test vector store connection timeout handling."""
        # Mock connection timeout
        mock_vector_store.connect.return_value = StepResult(
            success=False,
            error="Connection timeout: Service unavailable",
            retryable=True,
            custom_status="retryable",
        )

        result = await mock_vector_store.connect()

        assert not result.success
        assert result["status"] == "retryable"
        assert "Connection timeout" in result.error

    @pytest.mark.asyncio
    async def test_vector_store_authentication_failure(self, mock_vector_store: Mock) -> None:
        """Test vector store authentication failure handling."""
        # Mock authentication failure
        mock_vector_store.connect.return_value = StepResult(
            success=False,
            error="Authentication failed: Invalid credentials",
            custom_status="unauthorized",
        )

        result = await mock_vector_store.connect()

        assert not result.success
        assert result["status"] == "unauthorized"
        assert "Authentication failed" in result.error

    # Vector Store Operation Tests

    @pytest.mark.asyncio
    async def test_vector_store_insert_failure(
        self,
        mock_vector_store: Mock,
        sample_content: dict[str, Any],
        sample_embedding: list[float],
    ) -> None:
        """Test vector store insert operation failure."""
        # Mock insert failure
        mock_vector_store.insert.return_value = StepResult(
            success=False,
            error="Insert failed: Vector store unavailable",
            retryable=True,
            custom_status="retryable",
        )

        result = await mock_vector_store.insert(
            content=sample_content,
            embedding=sample_embedding,
            tenant="test_tenant",
            workspace="test_workspace",
        )

        assert not result.success
        assert result["status"] == "retryable"
        assert "Insert failed" in result.error

    @pytest.mark.asyncio
    async def test_vector_store_search_failure(self, mock_vector_store: Mock, sample_embedding: list[float]) -> None:
        """Test vector store search operation failure."""
        # Mock search failure
        mock_vector_store.search.return_value = StepResult(
            success=False,
            error="Search failed: Index corrupted",
            retryable=True,
            custom_status="retryable",
        )

        result = await mock_vector_store.search(
            query_embedding=sample_embedding,
            limit=10,
            tenant="test_tenant",
            workspace="test_workspace",
        )

        assert not result.success
        assert result["status"] == "retryable"
        assert "Search failed" in result.error

    @pytest.mark.asyncio
    async def test_vector_store_delete_failure(self, mock_vector_store: Mock) -> None:
        """Test vector store delete operation failure."""
        # Mock delete failure
        mock_vector_store.delete.return_value = StepResult(
            success=False,
            error="Delete failed: Vector not found",
            custom_status="bad_request",
        )

        result = await mock_vector_store.delete(
            vector_id="nonexistent_id", tenant="test_tenant", workspace="test_workspace"
        )

        assert not result.success
        assert result["status"] == "bad_request"
        assert "Delete failed" in result.error

    @pytest.mark.asyncio
    async def test_vector_store_update_failure(
        self,
        mock_vector_store: Mock,
        sample_content: dict[str, Any],
        sample_embedding: list[float],
    ) -> None:
        """Test vector store update operation failure."""
        # Mock update failure
        mock_vector_store.update.return_value = StepResult(
            success=False,
            error="Update failed: Version conflict",
            retryable=True,
            custom_status="retryable",
        )

        result = await mock_vector_store.update(
            vector_id="test_id",
            content=sample_content,
            embedding=sample_embedding,
            tenant="test_tenant",
            workspace="test_workspace",
        )

        assert not result.success
        assert result["status"] == "retryable"
        assert "Update failed" in result.error

    # Embedding Generation Tests

    def test_embedding_generation_failure(self, mock_embedding_service: Mock) -> None:
        """Test embedding generation failure."""
        # Mock embedding generation failure
        mock_embedding_service.generate_embedding.return_value = StepResult(
            success=False,
            error="Embedding generation failed: Model unavailable",
            retryable=True,
            custom_status="retryable",
        )

        result = mock_embedding_service.generate_embedding("sample text")

        assert not result.success
        assert result["status"] == "retryable"
        assert "Embedding generation failed" in result.error

    def test_embedding_invalid_input(self, mock_embedding_service: Mock) -> None:
        """Test embedding generation with invalid input."""
        # Mock invalid input error
        mock_embedding_service.generate_embedding.return_value = StepResult(
            success=False,
            error="Invalid input: Empty text provided",
            custom_status="bad_request",
        )

        result = mock_embedding_service.generate_embedding("")

        assert not result.success
        assert result["status"] == "bad_request"
        assert "Invalid input" in result.error

    def test_embedding_rate_limit_exceeded(self, mock_embedding_service: Mock) -> None:
        """Test embedding generation rate limiting."""
        # Mock rate limit error
        mock_embedding_service.generate_embedding.return_value = StepResult(
            success=False, error="Rate limit exceeded", custom_status="rate_limited"
        )

        result = mock_embedding_service.generate_embedding("sample text")

        assert not result.success
        assert result["status"] == "rate_limited"
        assert "Rate limit exceeded" in result.error

    def test_embedding_text_too_long(self, mock_embedding_service: Mock) -> None:
        """Test embedding generation with text that's too long."""
        long_text = "x" * 100000  # 100KB of text

        # Mock text too long error
        mock_embedding_service.generate_embedding.return_value = StepResult(
            success=False,
            error="Text too long: Exceeds maximum length",
            custom_status="bad_request",
        )

        result = mock_embedding_service.generate_embedding(long_text)

        assert not result.success
        assert result["status"] == "bad_request"
        assert "Text too long" in result.error

    # Search Timeout Tests

    @pytest.mark.asyncio
    async def test_vector_search_timeout(self, mock_vector_store: Mock, sample_embedding: list[float]) -> None:
        """Test vector search timeout handling."""
        # Mock search timeout
        mock_vector_store.search.return_value = StepResult(
            success=False,
            error="Search timeout: Query took too long",
            retryable=True,
            custom_status="retryable",
        )

        result = await mock_vector_store.search(
            query_embedding=sample_embedding,
            limit=100,  # Large limit that might cause timeout
            tenant="test_tenant",
            workspace="test_workspace",
        )

        assert not result.success
        assert result["status"] == "retryable"
        assert "Search timeout" in result.error

    @pytest.mark.asyncio
    async def test_semantic_search_timeout(self, mock_vector_store: Mock) -> None:
        """Test semantic search timeout handling."""
        # Mock semantic search timeout
        mock_vector_store.semantic_search.return_value = StepResult(
            success=False,
            error="Semantic search timeout: Complex query",
            retryable=True,
            custom_status="retryable",
        )

        result = await mock_vector_store.semantic_search(
            query="complex query with many terms",
            limit=50,
            tenant="test_tenant",
            workspace="test_workspace",
        )

        assert not result.success
        assert result["status"] == "retryable"
        assert "Semantic search timeout" in result.error

    # Tenant Isolation Tests

    @pytest.mark.asyncio
    async def test_tenant_isolation_during_failure(self, mock_vector_store: Mock) -> None:
        """Test tenant isolation maintained during system failures."""

        # Mock failure for one tenant but not another
        def mock_search_side_effect(query_embedding: list[float], tenant: str, **kwargs: Any) -> StepResult:
            if tenant == "failing_tenant":
                return StepResult(
                    success=False,
                    error="Tenant-specific failure",
                    retryable=True,
                    custom_status="retryable",
                )
            else:
                return StepResult.ok(results=[])

        mock_vector_store.search.side_effect = mock_search_side_effect

        # Test failing tenant
        failing_result = await mock_vector_store.search(
            query_embedding=[0.1, 0.2, 0.3],
            tenant="failing_tenant",
            workspace="test_workspace",
        )
        assert not failing_result.success
        assert "Tenant-specific failure" in failing_result.error

        # Test working tenant
        working_result = await mock_vector_store.search(
            query_embedding=[0.1, 0.2, 0.3],
            tenant="working_tenant",
            workspace="test_workspace",
        )
        assert working_result.success
        assert working_result["results"] == []

    @pytest.mark.asyncio
    async def test_workspace_isolation_during_failure(self, mock_vector_store: Mock) -> None:
        """Test workspace isolation maintained during system failures."""

        # Mock failure for one workspace but not another
        def mock_insert_side_effect(content: dict[str, Any], workspace: str, **kwargs: Any) -> StepResult:
            if workspace == "failing_workspace":
                return StepResult(
                    success=False,
                    error="Workspace-specific failure",
                    retryable=True,
                    custom_status="retryable",
                )
            else:
                return StepResult.ok(inserted=True)

        mock_vector_store.insert.side_effect = mock_insert_side_effect

        # Test failing workspace
        failing_result = await mock_vector_store.insert(
            content={"text": "sample"},
            embedding=[0.1, 0.2, 0.3],
            tenant="test_tenant",
            workspace="failing_workspace",
        )
        assert not failing_result.success
        assert "Workspace-specific failure" in failing_result.error

        # Test working workspace
        working_result = await mock_vector_store.insert(
            content={"text": "sample"},
            embedding=[0.1, 0.2, 0.3],
            tenant="test_tenant",
            workspace="working_workspace",
        )
        assert working_result.success
        assert working_result["inserted"] is True

    # Compaction Tests

    @pytest.mark.asyncio
    async def test_compaction_failure(self, mock_vector_store: Mock) -> None:
        """Test memory compaction failure handling."""
        # Mock compaction failure
        mock_vector_store.compact.return_value = StepResult(
            success=False,
            error="Compaction failed: Insufficient disk space",
            retryable=True,
            custom_status="retryable",
        )

        result = await mock_vector_store.compact(tenant="test_tenant", workspace="test_workspace")

        assert not result.success
        assert result["status"] == "retryable"
        assert "Compaction failed" in result.error

    @pytest.mark.asyncio
    async def test_compaction_timeout(self, mock_vector_store: Mock) -> None:
        """Test memory compaction timeout handling."""
        # Mock compaction timeout
        mock_vector_store.compact.return_value = StepResult(
            success=False,
            error="Compaction timeout: Operation took too long",
            retryable=True,
            custom_status="retryable",
        )

        result = await mock_vector_store.compact(tenant="test_tenant", workspace="test_workspace")

        assert not result.success
        assert result["status"] == "retryable"
        assert "Compaction timeout" in result.error

    @pytest.mark.asyncio
    async def test_compaction_during_active_operations(self, mock_vector_store: Mock) -> None:
        """Test compaction failure when operations are active."""
        # Mock compaction failure due to active operations
        mock_vector_store.compact.return_value = StepResult(
            success=False,
            error="Compaction failed: Active operations in progress",
            retryable=True,
            custom_status="retryable",
        )

        result = await mock_vector_store.compact(tenant="test_tenant", workspace="test_workspace")

        assert not result.success
        assert result["status"] == "retryable"
        assert "Active operations" in result.error

    # Memory Consistency Tests

    @pytest.mark.asyncio
    async def test_memory_consistency_check_failure(self, mock_vector_store: Mock) -> None:
        """Test memory consistency check failure."""
        # Mock consistency check failure
        mock_vector_store.check_consistency.return_value = StepResult(
            success=False,
            error="Consistency check failed: Data corruption detected",
            retryable=True,
            custom_status="retryable",
        )

        result = await mock_vector_store.check_consistency(tenant="test_tenant", workspace="test_workspace")

        assert not result.success
        assert result["status"] == "retryable"
        assert "Consistency check failed" in result.error

    @pytest.mark.asyncio
    async def test_memory_recovery_after_failure(self, mock_vector_store: Mock) -> None:
        """Test memory recovery after failure."""
        # Mock initial failure
        mock_vector_store.connect.return_value = StepResult(
            success=False,
            error="Connection failed",
            retryable=True,
            custom_status="retryable",
        )

        # First connection attempt fails
        result1 = await mock_vector_store.connect()
        assert not result1.success

        # Mock recovery
        mock_vector_store.connect.return_value = StepResult.ok(connected=True)

        # Second connection attempt succeeds
        result2 = await mock_vector_store.connect()
        assert result2.success
        assert result2["connected"] is True

    @pytest.mark.asyncio
    async def test_memory_backup_restore_failure(self, mock_vector_store: Mock) -> None:
        """Test memory backup and restore failure handling."""
        # Mock backup failure
        mock_vector_store.backup.return_value = StepResult(
            success=False,
            error="Backup failed: Storage unavailable",
            retryable=True,
            custom_status="retryable",
        )

        backup_result = await mock_vector_store.backup(tenant="test_tenant", workspace="test_workspace")

        assert not backup_result.success
        assert backup_result["status"] == "retryable"
        assert "Backup failed" in backup_result.error

    # Resource Exhaustion Tests

    @pytest.mark.asyncio
    async def test_memory_resource_exhaustion(self, mock_vector_store: Mock) -> None:
        """Test memory resource exhaustion handling."""
        # Mock resource exhaustion
        mock_vector_store.insert.return_value = StepResult(
            success=False,
            error="Resource exhaustion: Memory limit reached",
            retryable=True,
            custom_status="retryable",
        )

        result = await mock_vector_store.insert(
            content={"text": "large content"},
            embedding=[0.1] * 10000,  # Large embedding
            tenant="test_tenant",
            workspace="test_workspace",
        )

        assert not result.success
        assert result["status"] == "retryable"
        assert "Resource exhaustion" in result.error

    @pytest.mark.asyncio
    async def test_memory_disk_space_exhaustion(self, mock_vector_store: Mock) -> None:
        """Test memory disk space exhaustion handling."""
        # Mock disk space exhaustion
        mock_vector_store.insert.return_value = StepResult(
            success=False,
            error="Disk space exhausted",
            retryable=True,
            custom_status="retryable",
        )

        result = await mock_vector_store.insert(
            content={"text": "sample"},
            embedding=[0.1, 0.2, 0.3],
            tenant="test_tenant",
            workspace="test_workspace",
        )

        assert not result.success
        assert result["status"] == "retryable"
        assert "Disk space exhausted" in result.error

    # Cache Integration Tests

    def test_cache_integration_failure(self) -> None:
        """Test cache integration failure handling."""
        # Mock cache failure
        cache_error = StepResult(
            success=False,
            error="Cache integration failed: Redis unavailable",
            retryable=True,
            custom_status="retryable",
        )

        assert not cache_error.success
        assert cache_error["status"] == "retryable"
        assert "Cache integration failed" in cache_error.error

    @pytest.mark.asyncio
    async def test_cache_fallback_to_vector_store(self, mock_redis_client: Mock, mock_vector_store: Mock) -> None:
        """Test cache fallback to vector store when cache fails."""
        # Mock cache failure
        mock_redis_client.get.side_effect = ConnectionError("Cache unavailable")

        # Mock vector store fallback success
        mock_vector_store.search.return_value = StepResult.ok(results=[{"id": "1", "score": 0.9}])

        # Simulate cache failure and fallback
        try:
            await mock_redis_client.get("cache_key")
        except ConnectionError:
            # Fallback to vector store
            result = await mock_vector_store.search(
                query_embedding=[0.1, 0.2, 0.3],
                limit=10,
                tenant="test_tenant",
                workspace="test_workspace",
            )
            assert result.success
            assert len(result["results"]) == 1
            assert result["results"][0]["score"] == 0.9

    # Error Aggregation and Reporting Tests

    def test_memory_error_aggregation(self) -> None:
        """Test aggregation of multiple memory errors."""
        memory_errors = [
            StepResult(
                success=False,
                error="Vector store connection failed",
                retryable=True,
                custom_status="retryable",
            ),
            StepResult(
                success=False,
                error="Embedding generation failed",
                retryable=True,
                custom_status="retryable",
            ),
            StepResult(
                success=False,
                error="Search timeout",
                retryable=True,
                custom_status="retryable",
            ),
            StepResult(
                success=False,
                error="Compaction failed",
                retryable=True,
                custom_status="retryable",
            ),
        ]

        # Aggregate errors
        error_summary = {
            "total_failures": len(memory_errors),
            "error_types": list({error["status"] for error in memory_errors}),
            "error_messages": [error.error for error in memory_errors],
            "system_health": "degraded",
        }

        assert error_summary["total_failures"] == 4
        assert "retryable" in error_summary["error_types"]
        assert len(error_summary["error_messages"]) == 4
        assert error_summary["system_health"] == "degraded"

    def test_memory_error_context_preservation(self) -> None:
        """Test that memory error context is preserved."""
        error_context = {
            "operation": "vector_search",
            "tenant": "test_tenant",
            "workspace": "test_workspace",
            "query_size": 500,
            "timestamp": "2025-01-04T10:00:00Z",
        }

        # Mock error with context
        memory_error = StepResult(
            success=False,
            error="Vector search failed",
            retryable=True,
            custom_status="retryable",
            metadata=error_context,
        )

        assert memory_error.error == "Vector search failed"
        assert memory_error["status"] == "retryable"
        assert memory_error.metadata["operation"] == "vector_search"
        assert memory_error.metadata["tenant"] == "test_tenant"
        assert memory_error.metadata["workspace"] == "test_workspace"
